[2024-12-05T06:04:36.424+0000] {local_task_job_runner.py:123} INFO - ::group::Pre task execution logs
[2024-12-05T06:04:36.741+0000] {taskinstance.py:2613} INFO - Dependencies all met for dep_context=non-requeueable deps ti=<TaskInstance: openweathermap_weather_dag.process_weather_data scheduled__2024-12-04T00:00:00+00:00 [queued]>
[2024-12-05T06:04:36.763+0000] {taskinstance.py:2613} INFO - Dependencies all met for dep_context=requeueable deps ti=<TaskInstance: openweathermap_weather_dag.process_weather_data scheduled__2024-12-04T00:00:00+00:00 [queued]>
[2024-12-05T06:04:36.764+0000] {taskinstance.py:2866} INFO - Starting attempt 2 of 3
[2024-12-05T06:04:36.796+0000] {taskinstance.py:2889} INFO - Executing <Task(PythonOperator): process_weather_data> on 2024-12-04 00:00:00+00:00
[2024-12-05T06:04:36.813+0000] {warnings.py:112} WARNING - /home/***/.local/lib/python3.12/site-packages/***/task/task_runner/standard_task_runner.py:70: DeprecationWarning: This process (pid=75) is multi-threaded, use of fork() may lead to deadlocks in the child.
  pid = os.fork()

[2024-12-05T06:04:36.816+0000] {standard_task_runner.py:72} INFO - Started process 83 to run task
[2024-12-05T06:04:36.818+0000] {standard_task_runner.py:104} INFO - Running: ['***', 'tasks', 'run', 'openweathermap_weather_dag', 'process_weather_data', 'scheduled__2024-12-04T00:00:00+00:00', '--job-id', '20', '--raw', '--subdir', 'DAGS_FOLDER/dag_weather.py', '--cfg-path', '/tmp/tmpxdqgnxaq']
[2024-12-05T06:04:36.820+0000] {standard_task_runner.py:105} INFO - Job 20: Subtask process_weather_data
[2024-12-05T06:04:36.907+0000] {task_command.py:467} INFO - Running <TaskInstance: openweathermap_weather_dag.process_weather_data scheduled__2024-12-04T00:00:00+00:00 [running]> on host ba3c3d68bfd0
[2024-12-05T06:04:37.079+0000] {taskinstance.py:3132} INFO - Exporting env vars: AIRFLOW_CTX_DAG_OWNER='***' AIRFLOW_CTX_DAG_ID='openweathermap_weather_dag' AIRFLOW_CTX_TASK_ID='process_weather_data' AIRFLOW_CTX_EXECUTION_DATE='2024-12-04T00:00:00+00:00' AIRFLOW_CTX_TRY_NUMBER='2' AIRFLOW_CTX_DAG_RUN_ID='scheduled__2024-12-04T00:00:00+00:00'
[2024-12-05T06:04:37.081+0000] {logging_mixin.py:190} INFO - Task instance is in running state
[2024-12-05T06:04:37.082+0000] {logging_mixin.py:190} INFO -  Previous state of the Task instance: queued
[2024-12-05T06:04:37.082+0000] {logging_mixin.py:190} INFO - Current task name:process_weather_data state:running start_date:2024-12-05 06:04:36.743050+00:00
[2024-12-05T06:04:37.083+0000] {logging_mixin.py:190} INFO - Dag name:openweathermap_weather_dag and current dag run status:running
[2024-12-05T06:04:37.083+0000] {taskinstance.py:731} INFO - ::endgroup::
[2024-12-05T06:04:37.102+0000] {taskinstance.py:3311} ERROR - Task failed with exception
Traceback (most recent call last):
  File "/home/airflow/.local/lib/python3.12/site-packages/airflow/models/taskinstance.py", line 767, in _execute_task
    result = _execute_callable(context=context, **execute_callable_kwargs)
             ^^^^^^^^^^^^^^^^^^^^^^^^^^^^^^^^^^^^^^^^^^^^^^^^^^^^^^^^^^^^^
  File "/home/airflow/.local/lib/python3.12/site-packages/airflow/models/taskinstance.py", line 733, in _execute_callable
    return ExecutionCallableRunner(
           ^^^^^^^^^^^^^^^^^^^^^^^^
  File "/home/airflow/.local/lib/python3.12/site-packages/airflow/utils/operator_helpers.py", line 252, in run
    return self.func(*args, **kwargs)
           ^^^^^^^^^^^^^^^^^^^^^^^^^^
  File "/home/airflow/.local/lib/python3.12/site-packages/airflow/models/baseoperator.py", line 417, in wrapper
    return func(self, *args, **kwargs)
           ^^^^^^^^^^^^^^^^^^^^^^^^^^^
  File "/home/airflow/.local/lib/python3.12/site-packages/airflow/operators/python.py", line 238, in execute
    return_value = self.execute_callable()
                   ^^^^^^^^^^^^^^^^^^^^^^^
  File "/home/airflow/.local/lib/python3.12/site-packages/airflow/operators/python.py", line 256, in execute_callable
    return runner.run(*self.op_args, **self.op_kwargs)
           ^^^^^^^^^^^^^^^^^^^^^^^^^^^^^^^^^^^^^^^^^^^
  File "/home/airflow/.local/lib/python3.12/site-packages/airflow/utils/operator_helpers.py", line 252, in run
    return self.func(*args, **kwargs)
           ^^^^^^^^^^^^^^^^^^^^^^^^^^
  File "/opt/airflow/dags/dag_weather.py", line 32, in _process_weather_data
    for city_data in weather_data:
                     ^^^^^^^^^^^^
TypeError: 'NoneType' object is not iterable
[2024-12-05T06:04:37.128+0000] {logging_mixin.py:190} INFO - Task instance in failure state
[2024-12-05T06:04:37.129+0000] {logging_mixin.py:190} INFO - Task start:2024-12-05 06:04:36.743050+00:00 end:2024-12-05 06:04:37.128072+00:00 duration:0.385022
[2024-12-05T06:04:37.130+0000] {logging_mixin.py:190} INFO - Task:<Task(PythonOperator): process_weather_data> dag:<DAG: openweathermap_weather_dag> dagrun:<DagRun openweathermap_weather_dag @ 2024-12-04 00:00:00+00:00: scheduled__2024-12-04T00:00:00+00:00, state:running, queued_at: 2024-12-05 05:48:27.297648+00:00. externally triggered: False>
[2024-12-05T06:04:37.130+0000] {logging_mixin.py:190} INFO - Failure caused by 'NoneType' object is not iterable
[2024-12-05T06:04:37.131+0000] {taskinstance.py:1225} INFO - Marking task as UP_FOR_RETRY. dag_id=openweathermap_weather_dag, task_id=process_weather_data, run_id=scheduled__2024-12-04T00:00:00+00:00, execution_date=20241204T000000, start_date=20241205T060436, end_date=20241205T060437
[2024-12-05T06:04:37.157+0000] {taskinstance.py:340} INFO - ::group::Post task execution logs
[2024-12-05T06:04:37.158+0000] {standard_task_runner.py:124} ERROR - Failed to execute job 20 for task process_weather_data ('NoneType' object is not iterable; 83)
Traceback (most recent call last):
  File "/home/airflow/.local/lib/python3.12/site-packages/airflow/task/task_runner/standard_task_runner.py", line 117, in _start_by_fork
    ret = args.func(args, dag=self.dag)
          ^^^^^^^^^^^^^^^^^^^^^^^^^^^^^
  File "/home/airflow/.local/lib/python3.12/site-packages/airflow/cli/cli_config.py", line 49, in command
    return func(*args, **kwargs)
           ^^^^^^^^^^^^^^^^^^^^^
  File "/home/airflow/.local/lib/python3.12/site-packages/airflow/utils/cli.py", line 116, in wrapper
    return f(*args, **kwargs)
           ^^^^^^^^^^^^^^^^^^
  File "/home/airflow/.local/lib/python3.12/site-packages/airflow/cli/commands/task_command.py", line 483, in task_run
    task_return_code = _run_task_by_selected_method(args, _dag, ti)
                       ^^^^^^^^^^^^^^^^^^^^^^^^^^^^^^^^^^^^^^^^^^^^
  File "/home/airflow/.local/lib/python3.12/site-packages/airflow/cli/commands/task_command.py", line 256, in _run_task_by_selected_method
    return _run_raw_task(args, ti)
           ^^^^^^^^^^^^^^^^^^^^^^^
  File "/home/airflow/.local/lib/python3.12/site-packages/airflow/cli/commands/task_command.py", line 341, in _run_raw_task
    return ti._run_raw_task(
           ^^^^^^^^^^^^^^^^^
  File "/home/airflow/.local/lib/python3.12/site-packages/airflow/utils/session.py", line 97, in wrapper
    return func(*args, session=session, **kwargs)
           ^^^^^^^^^^^^^^^^^^^^^^^^^^^^^^^^^^^^^^
  File "/home/airflow/.local/lib/python3.12/site-packages/airflow/models/taskinstance.py", line 3005, in _run_raw_task
    return _run_raw_task(
           ^^^^^^^^^^^^^^
  File "/home/airflow/.local/lib/python3.12/site-packages/airflow/models/taskinstance.py", line 273, in _run_raw_task
    TaskInstance._execute_task_with_callbacks(
  File "/home/airflow/.local/lib/python3.12/site-packages/airflow/models/taskinstance.py", line 3159, in _execute_task_with_callbacks
    result = self._execute_task(context, task_orig)
             ^^^^^^^^^^^^^^^^^^^^^^^^^^^^^^^^^^^^^^
  File "/home/airflow/.local/lib/python3.12/site-packages/airflow/models/taskinstance.py", line 3183, in _execute_task
    return _execute_task(self, context, task_orig)
           ^^^^^^^^^^^^^^^^^^^^^^^^^^^^^^^^^^^^^^^
  File "/home/airflow/.local/lib/python3.12/site-packages/airflow/models/taskinstance.py", line 767, in _execute_task
    result = _execute_callable(context=context, **execute_callable_kwargs)
             ^^^^^^^^^^^^^^^^^^^^^^^^^^^^^^^^^^^^^^^^^^^^^^^^^^^^^^^^^^^^^
  File "/home/airflow/.local/lib/python3.12/site-packages/airflow/models/taskinstance.py", line 733, in _execute_callable
    return ExecutionCallableRunner(
           ^^^^^^^^^^^^^^^^^^^^^^^^
  File "/home/airflow/.local/lib/python3.12/site-packages/airflow/utils/operator_helpers.py", line 252, in run
    return self.func(*args, **kwargs)
           ^^^^^^^^^^^^^^^^^^^^^^^^^^
  File "/home/airflow/.local/lib/python3.12/site-packages/airflow/models/baseoperator.py", line 417, in wrapper
    return func(self, *args, **kwargs)
           ^^^^^^^^^^^^^^^^^^^^^^^^^^^
  File "/home/airflow/.local/lib/python3.12/site-packages/airflow/operators/python.py", line 238, in execute
    return_value = self.execute_callable()
                   ^^^^^^^^^^^^^^^^^^^^^^^
  File "/home/airflow/.local/lib/python3.12/site-packages/airflow/operators/python.py", line 256, in execute_callable
    return runner.run(*self.op_args, **self.op_kwargs)
           ^^^^^^^^^^^^^^^^^^^^^^^^^^^^^^^^^^^^^^^^^^^
  File "/home/airflow/.local/lib/python3.12/site-packages/airflow/utils/operator_helpers.py", line 252, in run
    return self.func(*args, **kwargs)
           ^^^^^^^^^^^^^^^^^^^^^^^^^^
  File "/opt/airflow/dags/dag_weather.py", line 32, in _process_weather_data
    for city_data in weather_data:
                     ^^^^^^^^^^^^
TypeError: 'NoneType' object is not iterable
[2024-12-05T06:04:37.193+0000] {local_task_job_runner.py:266} INFO - Task exited with return code 1
[2024-12-05T06:04:37.239+0000] {taskinstance.py:3895} INFO - 0 downstream tasks scheduled from follow-on schedule check
[2024-12-05T06:04:37.241+0000] {local_task_job_runner.py:245} INFO - ::endgroup::
